Workbook
Name OLE_LINK1: 'Annex 3 Preserved charges'!#REF!

Sheet Overview
A2: Company and Licence name, charging year, effective from, status
B3: Company and Licence name | C3: Year | D3: Effective From | E3: Status
A4: Company and Licence name, charging year, effective from, status | B4: London Power Networks | C4: 2027/28 | D4: 1 April 2027 | E4: Final
A6: List of data tables in this workbook
A7: Worksheet | B7: Information
A8: Annex 1 LV, HV and Unmetered Supplies charges | B8: Annex 1 contains the charges to LV and HV Designated Properties and Unmetered Supplies.
A9: Annex 2 Designated EHV charges | B9: ="Annex 2 contains the charges to Designated EHV Properties and charges applied to LDNOs with Designated EHV Properties/end-users embedded in networks within the " &B4 &" Licence area." -> Annex 2 contains the charges to Designated EHV Properties and charges applied to LDNOs with Designated EHV Properties/end-users embedded in networks within the London Power Networks Licence area.
A10: Annex 3 Preserved charges | B10: Annex 3 contains details of any preserved and additional charges that are valid at this time.
A11: Annex 4 LDNO charges | B11: ="Annex 4 contains charges that are levied on the owner of an embedded network within the "&B4&" Licence area. "&"Electricity suppliers and consumers who have properties connected to an embedded network should contact the embedded network owner to determine their distribution charges."&" The charges listed in this table are not payable by domestic consumers, business consumers or electricity suppliers." -> Annex 4 contains charges that are levied on the owner of an embedded network within the London Power Networks Licence area. Electricity suppliers and consumers who have properties connected to an embedded network should contact the embedded network owner to determine their distribution charges. The charges listed in this table are not payable by domestic consumers, business consumers or electricity suppliers.
A12: Annex 5 LLFs | B12: Annex 5 has been intentionally left blank as this charging statement is published a complete year before the LLFs have been audited. The line loss factors that are approved by the BSC Panel for the applicable year and consequently published on the Elexon website will take precedence and be used in Settlement. This annex will be re-published with these values once they are available.
A13: Annex 6 Charges for New or Amended Designated EHV Properties | B13: ="Annex 6 contains the charges for new or amended Designated EHV Properties and charges applied to LDNOs with new or amended Designated EHV Properties/end-users embedded in networks within the " &B4 &" Licence area." -> Annex 6 contains the charges for new or amended Designated EHV Properties and charges applied to LDNOs with new or amended Designated EHV Properties/end-users embedded in networks within the London Power Networks Licence area.
A14: Annex 7 Fixed adders for Supplier of Last Resort and Eligible Bad Debt pass-through costs | B14: Annex 7 contains the fixed adders to recover Supplier of Last Resort and Eligible Bad Debt pass-through costs. The Excess Supplier of Last Resort fixed adder relates to an increase to previously published charges only.
A15: Nodal prices | B15: Contains the underlying nodal costs used to calculate the current EDCM charges.
A16: SSC unit rate lookup | B16: Contains a mapping of Standard Settlement Configurations to common decodings
A17: Residual Charging Bandings | B17: Contains the four Residual charging band allocation for Customers
A18: TNUoS Mapping | B18: Contains a mapping of DUoS Tariffs to TNUoS Site Charging Bands
A19: Charge calculator | B19: Charge calculator is a tool to help you estimate your distribution charges using current consumption data and forecast consumption data.
A21: Notes to users of this spreadsheet
A23: Please use this spreadsheet with reference to the LC14 use of system charging statement.
A25: Notes to DNOs populating this spreadsheet
A27: DNOs must endeavour to maintain consistency in the structure of this spreadsheet. Any changes to the structure must be noted in the 'Notes to users of this spreadsheet'
A28: The drop down list on the charge calculator can be expanded by unprotecting the charge calculator sheet and selecting 'data', 'data validation...' and then expanding the 'source' data range. The sheet can then be protected.

Sheet Annex 1 LV, HV and UMS charges
A1: Back to Overview
A2: =Overview!B4& " - Effective from "&Overview!D4&" - "&Overview!E4&" LV and HV charges" -> London Power Networks - Effective from 1 April 2027 - Final LV and HV charges
A4: Time Bands for LV and HV Designated Properties | G4: Time Bands for Unmetered Properties
A5: Time periods | B5: Red Time Band | C5: Amber Time Band | E5: Green Time Band | I5: Black Time Band | J5: Yellow Time Band | K5: Green Time Band
A6: Monday to Friday (Including Bank Holidays) All Year | B6: 11:00 - 14:00 16:00 - 19:00 | C6: 07:00 - 11:00 14:00 - 16:00 19:00 - 23:00 | E6: 00:00 - 07:00 23:00 - 24:00 | G6: Monday to Friday (Including Bank Holidays) June to August Inclusive | I6: 11:00 - 14:00 | J6: 07:00 - 11:00 14:00 - 23:00 | K6: 00:00 - 07:00 23:00 - 24:00
A7: Saturday and Sunday All Year | E7: 00:00 - 24:00 | G7: Monday to Friday (Including Bank Holidays) November to February Inclusive | I7: 16:00 - 19:00 | J7: 07:00 - 16:00 19:00 - 23:00 | K7: 00:00 - 07:00 23:00 - 24:00
A8: Notes | B8: All the above times are in UK Clock time | G8: Monday to Friday (Including Bank Holidays) March, April, May and September, October | J8: 07:00 - 23:00 | K8: 00:00 - 07:00 23:00 - 24:00
G9: Saturday and Sunday All year | K9: 00:00 - 24:00
G10: Notes | I10: All the above times are in UK Clock time
A12: Tariff name | B12: Open LLFCs/ DUoS Tariff IDs | C12: PCs | D12: Red/black unit charge p/kWh | E12: Amber/yellow unit charge p/kWh | F12: Green unit charge p/kWh | G12: Fixed charge p/MPAN/day | H12: Capacity charge p/kVA/day | I12: Exceeded capacity charge p/kVA/day | J12: Reactive power charge p/kVArh | K12: Closed LLFCs/ DUoS Tariff IDs
A13: Domestic Aggregated or CT with Residual | B13: 1 | C13: 0, 1, 2 | D13: 12.197 | E13: 1.243 | F13: 0 | G13: 0 | K13: 902
A14: Domestic Aggregated (Related MPAN) | B14: 2 | C14: 2 | D14: 12.414 | E14: 1.46 | F14: 0.108
A15: Non-Domestic Aggregated or CT No Residual | B15: 199 | C15: 0, 3, 4, 5-8 | D15: 9.611 | E15: 1.13 | F15: 0.083 | G15: 5.91
A16: Non-Domestic Aggregated or CT Band 1 | B16: 201, N01 | C16: 0, 3, 4, 5-8 | D16: 9.491 | E16: 1.01 | F16: 0 | G16: 0
A17: Non-Domestic Aggregated or CT Band 2 | B17: 202, N02 | C17: 0, 3, 4, 5-8 | D17: 8.644 | E17: 0.164 | F17: 0 | G17: 0
A18: Non-Domestic Aggregated or CT Band 3 | B18: 203, N03 | C18: 0, 3, 4, 5-8 | D18: 8.334 | E18: 0 | F18: 0 | G18: 0
A19: Non-Domestic Aggregated or CT Band 4 | B19: 204, N04 | C19: 0, 3, 4, 5-8 | D19: 7.932 | E19: 0 | F19: 0 | G19: 0
A20: Non-Domestic Aggregated (Related MPAN) | B20: 200 | C20: 4 | D20: 9.611 | E20: 1.13 | F20: 0.083
A21: LV Site Specific No Residual | B21: 70 | C21: 0 | D21: 7.639 | E21: 0.922 | F21: 0.062 | G21: 14.51 | H21: 8.26 | I21: 8.26 | J21: 0.588
A22: LV Site Specific Band 1 | B22: 71 | C22: 0 | D22: 4.886 | E22: 0.322 | F22: 0.03 | G22: 2.3 | H22: 8.26 | I22: 8.26 | J22: 0.588
A23: LV Site Specific Band 2 | B23: 72 | C23: 0 | D23: 4.821 | E23: 0.322 | F23: 0.03 | G23: 2.3 | H23: 8.26 | I23: 8.26 | J23: 0.588
A24: LV Site Specific Band 3 | B24: 73 | C24: 0 | D24: 4.763 | E24: 0.322 | F24: 0.03 | G24: 2.3 | H24: 8.26 | I24: 8.26 | J24: 0.588
A25: LV Site Specific Band 4 | B25: 74 | C25: 0 | D25: 4.692 | E25: 0.322 | F25: 0.03 | G25: 2.3 | H25: 8.26 | I25: 8.26 | J25: 0.588
A26: LV Sub Site Specific No Residual | B26: 80 | C26: 0 | D26: 4.691 | E26: 0.599 | F26: 0.033 | G26: 12.21 | H26: 10.38 | I26: 10.38 | J26: 0.348
A27: LV Sub Site Specific Band 1 | B27: 81 | C27: 0 | D27: 1.938 | E27: 0 | F27: 0 | G27: 0 | H27: 10.38 | I27: 10.38 | J27: 0.348
A28: LV Sub Site Specific Band 2 | B28: 82 | C28: 0 | D28: 1.873 | E28: 0 | F28: 0 | G28: 0 | H28: 10.38 | I28: 10.38 | J28: 0.348
A29: LV Sub Site Specific Band 3 | B29: 83 | C29: 0 | D29: 1.815 | E29: 0 | F29: 0 | G29: 0 | H29: 10.38 | I29: 10.38 | J29: 0.348
A30: LV Sub Site Specific Band 4 | B30: 84 | C30: 0 | D30: 1.743 | E30: 0 | F30: 0 | G30: 0 | H30: 10.38 | I30: 10.38 | J30: 0.348
A31: HV Site Specific No Residual | B31: 90 | C31: 0 | D31: 3.488 | E31: 0.446 | F31: 0.026 | G31: 129.42 | H31: 10.65 | I31: 10.65 | J31: 0.271
A32: HV Site Specific Band 1 | B32: 91 | C32: 0 | D32: 0.42 | E32: 0 | F32: 0 | G32: 0 | H32: 10.65 | I32: 10.65 | J32: 0.271
... A35: HV Site Specific Band 4 | B35: 94 | C35: 0 | D35: 0.24 | E35: 0 | F35: 0 | G35: 0 | H35: 10.65 | I35: 10.65 | J35: 0.271
A36: Unmetered Supplies | B36: 350, 420, 421, 422, 423 | C36: 0, 1 or 8 | D36: 40.972 | E36: 3.346 | F36: 0.471 | K36: 424, 425, 426, 427, 428, 429, 430, 431, 432, 433, 434, 435
A37: LV Generation Aggregated | B37: 932 | C37: 0, 8 | D37: -7.828 | E37: -0.921 | F37: -0.068 | G37: 0
A38: LV Sub Generation Aggregated | C38: 0 | D38: -6.433 | E38: -0.769 | F38: -0.054 | G38: 0
A39: LV Generation Site Specific | B39: 980 | C39: 0 | D39: -7.828 | E39: -0.921 | F39: -0.068 | G39: 0 | J39: 0.55
A40: LV Generation Site Specific no RP Charge | B40: 981 | C40: 0 | D40: -7.828 | E40: -0.921 | F40: -0.068 | G40: 0
A41: LV Sub Generation Site Specific | B41: 984 | C41: 0 | D41: -6.433 | E41: -0.769 | F41: -0.054 | G41: 0 | J41: 0.433
A42: LV Sub Generation Site Specific no RP Charge | B42: 985 | C42: 0 | D42: -6.433 | E42: -0.769 | F42: -0.054 | G42: 0
A43: HV Generation Site Specific | B43: 988 | C43: 0 | D43: -4.179 | E43: -0.534 | F43: -0.029 | G43: 9.08 | J43: 0.382
A44: HV Generation Site Specific no RP Charge | B44: 989 | C44: 0 | D44: -4.179 | E44: -0.534 | F44: -0.029 | G44: 9.08

Sheet Annex 2 Designated EHV charges
A1: Back to Overview | C1: Note: The DNO reserves the right to apply the listed charges to any other MPANs/MSIDs associated with the site. This includes reallocating charges to a traded MPAN at the same site where another MPAN has been disconnected or de-energised.
A2: =Overview!B4& " - Effective from "&Overview!D4&" - "&Overview!E4&" Designated EHV charges" -> London Power Networks - Effective from 1 April 2027 - Final Designated EHV charges
A4: Time Periods for Designated EHV Properties
A5: Time periods | D5: Super Red Time Band
A6: Monday to Friday (Including Bank Holidays) June to August Inclusive | D6: 11:00 - 14:00
A7: Monday to Friday (Including Bank Holidays) November to February Inclusive | D7: 16:00 - 19:00
A8: Notes | D8: All the above times are in UK Clock time
A10: Import Unique Identifier | B10: LLFC/ DUoS Tariff ID | C10: Import MPANs/MSIDs | D10: Export Unique Identifier | E10: LLFC/ DUoS Tariff ID | F10: Export MPANs/MSIDs | G10: Name | H10: Residual Charging Band | I10: Import Super Red unit charge (p/kWh) | J10: Import fixed charge (p/day) | K10: Import capacity charge (p/kVA/day) | L10: Import exceeded capacity charge (p/kVA/day) | M10: Export Super Red unit charge (p/kWh) | N10: Export fixed charge (p/day) | O10: Export capacity charge (p/kVA/day) | P10: Export exceeded capacity charge (p/kVA/day)
A11: 21MOOR | B11: 854 | C11: 1200062747376;1200062747385 | G11: 21MOOR | H11: 2 | I11: 0.219 | J11: 11254.69 | K11: 2.68 | L11: 2.68
A12: 22BSHP | B12: 810 | C12: 1200062355497;1200062355502 | G12: 22BSHP | H12: 3 | I12: 0.208 | J12: 28784.81 | K12: 2.74 | L12: 2.74
A13: BISHPC | B13: 811 | C13: 1200061143976;1200061143985 | G13: BISHPC | H13: 3 | I13: 0.197 | J13: 28784.81 | K13: 2.74 | L13: 2.74
A14: BLMBGN | B14: 820 | C14: 1200061385700;1200061385710 | G14: BLMBGN | H14: 2 | I14: 0.216 | J14: 11254.69 | K14: 2.59 | L14: 2.59
A15: BLMBGS | B15: 821 | C15: 1200061385729;1200061385738 | G15: BLMBGS | H15: 2 | I15: 0.215 | J15: 11254.69 | K15: 1.96 | L15: 1.96
A16: BRDGTE | B16: 805 | C16: 1200061148014;1200061148023 | G16: BRDGTE | H16: 2 | I16: 0.207 | J16: 11254.69 | K16: 3.34 | L16: 3.34
A17: BRKFLD | B17: 829 | C17: 1200061148060;1200061148079 | G17: BRKFLD | H17: 2 | I17: 0.22 | J17: 11254.69 | K17: 2.62 | L17: 2.62
A18: BRMLEY | C18: MSID: 1630 | G18: BRMLEY | H18: 4 | I18: 0.212 | J18: 68626.32 | K18: 5.1 | L18: 5.1
A19: CRLIMM | B19: 812 | C19: 1200062090483;1200062090492 | G19: CRLIMM | H19: 4 | I19: 0.003 | J19: 82036.16 | K19: 1.5 | L19: 1.5
A20: DART11 | C20: MSID: 1032 | G20: DART11 | H20: 2 | I20: 0.285 | J20: 10677.01 | K20: 6.51 | L20: 6.51
A21: DART33 | C21: MSID: 1032 | G21: DART33 | H21: 3 | I21: 0.603 | J21: 28207.13 | K21: 7.02 | L21: 7.02
A22: EPNLEI | C22: MSID: 1628 | G22: EPNLEI | H22: 4 | I22: 0.024 | J22: 68626.32 | K22: 5.2 | L22: 5.2
A23: FENAVE | B23: 813 | C23: 1200062132159;1200062132168 | G23: FENAVE | H23: 2 | I23: 0.205 | J23: 11254.69 | K23: 2.13 | L23: 2.13
A24: FENCHS | B24: 800 | C24: 1200061144029;1200061144038 | G24: FENCHS | H24: 2 | I24: 0.26 | J24: 11254.69 | K24: 2.81 | L24: 2.81
A25: GBLSWI | B25: 843 | C25: 1200050913681;1200050913690;1200050913706;1200050913715 | G25: GBLSWI | H25: 4 | I25: 0.003 | J25: 80311.31 | K25: 2.44 | L25: 2.44
A26: KNGLPN | C26: MSID: 1027 | G26: KNGLPN | H26: 2 | I26: 0 | J26: 10677.01 | K26: 4.92 | L26: 4.92
A27: LEDNHS | B27: 808 | C27: 1200061144065;1200061144074 | G27: LEDNHS | H27: 2 | I27: 0.2 | J27: 11254.69 | K27: 2.65 | L27: 2.65
A28: LIMEST | B28: 814 | C28: 1200062132006;1200062132015 | G28: LIMEST | H28: 2 | I28: 0.209 | J28: 11254.69 | K28: 2.44 | L28: 2.44
A29: LNWAL1 | B29: 816 | C29: 1200061148194;1200061148200 | G29: LNWAL1 | H29: 1 | I29: 0.217 | J29: 1553.35 | K29: 3.41 | L29: 3.41
A30: LNWALL | B30: 816 | C30: 1200061953070;1200061953089 | G30: LNWALL | H30: 2 | I30: 0.217 | J30: 11254.69 | K30: 1.42 | L30: 1.42
A31: LU_ACT | C31: MSID: 1631 | G31: LU_ACT | H31: 3 | I31: 0 | J31: 28589.8 | K31: 2.51 | L31: 2.51
A32: LU_CAN | B32: 818 | C32: 1200060323207;1200060323216 | G32: LU_CAN | H32: 4 | I32: 0 | J32: 79377.14 | K32: 2.32 | L32: 2.32
A33: LU_CHA | B33: 801 | C33: 1200061231921;1200061231930;1200061231940;1200061231959 | G33: LU_CHA | H33: 4 | I33: 0 | J33: 79971.42 | K33: 1.74 | L33: 1.74
A34: LU_HOX | B34: 804 | C34: 1200060323191 | G34: LU_HOX | H34: 4 | I34: 0 | J34: 77804.46 | K34: 0.68 | L34: 0.68
A35: LU_LOT | B35: 838 | C35: 1200050376902;1200050376911 | G35: LU_LOT | H35: 4 | I35: 0.001 | J35: 111285.72 | K35: 2.81 | L35: 2.81
A36: LU_MAN | B36: 837 | C36: 1200010200926 | G36: LU_MAN | H36: 4 | I36: 0.002 | J36: 98926.85 | K36: 2.34 | L36: 2.34
A37: LU_STE | B37: 839 | C37: 1200010157225;1200010157234 | G37: LU_STE | H37: 4 | I37: 0 | J37: 78217.28 | K37: 3.81 | L37: 3.81
A38: MRKLNE | B38: 806 | C38: 1200061378624;1200061378633 | G38: MRKLNE | H38: 1 | I38: 0.237 | J38: 1553.35 | K38: 2.19 | L38: 2.19
A39: NGC_BA | B39: 817 | C39: 1200010151863;1200010151872 | G39: NGC_BA | H39: 1 | I39: 0 | J39: 975.67 | K39: 0.86 | L39: 0.86
A40: NR_BOW | B40: 807 | C40: 1200060280440;1200060280468 | D40: NR_BOW | E40: 707 | F40: 1200060280430;1200060280459 | G40: NR_BOW | H40: 3 | I40: 0.008 | J40: 36853.77 | K40: 4.32 | L40: 4.32
A41: NR_BRO | B41: 847 | C41: 1200010251559 | G41: NR_BRO | H41: 4 | I41: 0.13 | J41: 72138.7 | K41: 3.11 | L41: 3.11
A42: NR_CIT | B42: 846 | C42: 1200010251521 | G42: NR_CIT | H42: 1 | I42: 0.002 | J42: 1103.23 | K42: 1.61 | L42: 1.61
...

Sheet Annex 2a Import
A1: Note: The list of MPANs / MSIDs provided may be incomplete; the DNO reserves the right to apply the listed charges to any other MPANs / MSIDs associated with the site. Note: This table is automatically populated based on the content of the tab entitled 'Annex 2 Designated EHV charges'. The timebands are as shown in Annex 2.
A2: =Overview!B4& " - Effective from "&Overview!D4&" - "&Overview!E4&" Designated EHV import charges" -> London Power Networks - Effective from 1 April 2027 - Final Designated EHV import charges
A4: Import Unique Identifier | B4: LLFC/ DUoS Tariff ID | C4: Import MPANs/MSIDs | D4: Name | E4: ='Annex 2 Designated EHV charges'!I10 -> Import Super Red unit charge (p/kWh) | F4: ='Annex 2 Designated EHV charges'!J10 -> Import fixed charge (p/day) | G4: ='Annex 2 Designated EHV charges'!K10 -> Import capacity charge (p/kVA/day) | H4: ='Annex 2 Designated EHV charges'!L10 -> Import exceeded capacity charge (p/kVA/day)
A5: {=IFERROR(INDEX('Annex 2 Designated EHV charges'!$A$11:$A$58, MATCH(0, IF(ISBLANK('Annex 2 Designated EHV charges'!$A$11:$A$58),1, COUNTIF(A$4:$A4, 'Annex 2 Designated EHV charges'!$A$11:$A$58)), 0)),"")} -> 21MOOR | B5: =IF($A5="","",VLOOKUP($A5,'Annex 2 Designated EHV charges'!$A:$O,2,0)) -> 854 | C5: =IF($A5="","",VLOOKUP($A5,'Annex 2 Designated EHV charges'!$A:$O,3,0)) -> 1200062747376;1200062747385 | D5: =IF($A5="","",VLOOKUP($A5,'Annex 2 Designated EHV charges'!$A:$O,7,0)) -> 21MOOR | E5: =IFERROR(IF(VLOOKUP($A5,'Annex 2 Designated EHV charges'!$A:$P,9,FALSE)=0,"",VLOOKUP($A5,'Annex 2 Designated EHV charges'!$A:$P,9,FALSE)),"") -> 0.219 | F5: =IFERROR(IF(VLOOKUP($A5,'Annex 2 Designated EHV charges'!$A:$P,10,FALSE)=0,"",VLOOKUP($A5,'Annex 2 Designated EHV charges'!$A:$P,10,FALSE)),"") -> 11254.69 | G5: =IFERROR(IF(VLOOKUP($A5,'Annex 2 Designated EHV charges'!$A:$P,11,FALSE)=0,"",VLOOKUP($A5,'Annex 2 Designated EHV charges'!$A:$P,11,FALSE)),"") -> 2.68 | H5: =IFERROR(IF(VLOOKUP($A5,'Annex 2 Designated EHV charges'!$A:$P,12,FALSE)=0,"",VLOOKUP($A5,'Annex 2 Designated EHV charges'!$A:$P,12,FALSE)),"") -> 2.68
A6: {=IFERROR(INDEX('Annex 2 Designated EHV charges'!$A$11:$A$58, MATCH(0, IF(ISBLANK('Annex 2 Designated EHV charges'!$A$11:$A$58),1, COUNTIF(A$4:$A5, 'Annex 2 Designated EHV charges'!$A$11:$A$58)), 0)),"")} -> 22BSHP | B6: =IF($A6="","",VLOOKUP($A6,'Annex 2 Designated EHV charges'!$A:$O,2,0)) -> 810 | C6: =IF($A6="","",VLOOKUP($A6,'Annex 2 Designated EHV charges'!$A:$O,3,0)) -> 1200062355497;1200062355502 | D6: =IF($A6="","",VLOOKUP($A6,'Annex 2 Designated EHV charges'!$A:$O,7,0)) -> 22BSHP | E6: =IFERROR(IF(VLOOKUP($A6,'Annex 2 Designated EHV charges'!$A:$P,9,FALSE)=0,"",VLOOKUP($A6,'Annex 2 Designated EHV charges'!$A:$P,9,FALSE)),"") -> 0.208 | F6: =IFERROR(IF(VLOOKUP($A6,'Annex 2 Designated EHV charges'!$A:$P,10,FALSE)=0,"",VLOOKUP($A6,'Annex 2 Designated EHV charges'!$A:$P,10,FALSE)),"") -> 28784.81 | G6: =IFERROR(IF(VLOOKUP($A6,'Annex 2 Designated EHV charges'!$A:$P,11,FALSE)=0,"",VLOOKUP($A6,'Annex 2 Designated EHV charges'!$A:$P,11,FALSE)),"") -> 2.74 | H6: =IFERROR(IF(VLOOKUP($A6,'Annex 2 Designated EHV charges'!$A:$P,12,FALSE)=0,"",VLOOKUP($A6,'Annex 2 Designated EHV charges'!$A:$P,12,FALSE)),"") -> 2.74
A7: {=IFERROR(INDEX('Annex 2 Designated EHV charges'!$A$11:$A$58, MATCH(0, IF(ISBLANK('Annex 2 Designated EHV charges'!$A$11:$A$58),1, COUNTIF(A$4:$A6, 'Annex 2 Designated EHV charges'!$A$11:$A$58)), 0)),"")} -> BISHPC | B7: =IF($A7="","",VLOOKUP($A7,'Annex 2 Designated EHV charges'!$A:$O,2,0)) -> 811 | C7: =IF($A7="","",VLOOKUP($A7,'Annex 2 Designated EHV charges'!$A:$O,3,0)) -> 1200061143976;1200061143985 | D7: =IF($A7="","",VLOOKUP($A7,'Annex 2 Designated EHV charges'!$A:$O,7,0)) -> BISHPC | E7: =IFERROR(IF(VLOOKUP($A7,'Annex 2 Designated EHV charges'!$A:$P,9,FALSE)=0,"",VLOOKUP($A7,'Annex 2 Designated EHV charges'!$A:$P,9,FALSE)),"") -> 0.197 | F7: =IFERROR(IF(VLOOKUP($A7,'Annex 2 Designated EHV charges'!$A:$P,10,FALSE)=0,"",VLOOKUP($A7,'Annex 2 Designated EHV charges'!$A:$P,10,FALSE)),"") -> 28784.81 | G7: =IFERROR(IF(VLOOKUP($A7,'Annex 2 Designated EHV charges'!$A:$P,11,FALSE)=0,"",VLOOKUP($A7,'Annex 2 Designated EHV charges'!$A:$P,11,FALSE)),"") -> 2.74 | H7: =IFERROR(IF(VLOOKUP($A7,'Annex 2 Designated EHV charges'!$A:$P,12,FALSE)=0,"",VLOOKUP($A7,'Annex 2 Designated EHV charges'!$A:$P,12,FALSE)),"") -> 2.74
A8: {=IFERROR(INDEX('Annex 2 Designated EHV charges'!$A$11:$A$58, MATCH(0, IF(ISBLANK('Annex 2 Designated EHV charges'!$A$11:$A$58),1, COUNTIF(A$4:$A7, 'Annex 2 Designated EHV charges'!$A$11:$A$58)), 0)),"")} -> BLMBGN | B8: =IF($A8="","",VLOOKUP($A8,'Annex 2 Designated EHV charges'!$A:$O,2,0)) -> 820 | C8: =IF($A8="","",VLOOKUP($A8,'Annex 2 Designated EHV charges'!$A:$O,3,0)) -> 1200061385700;1200061385710 | D8: =IF($A8="","",VLOOKUP($A8,'Annex 2 Designated EHV charges'!$A:$O,7,0)) -> BLMBGN | E8: =IFERROR(IF(VLOOKUP($A8,'Annex 2 Designated EHV charges'!$A:$P,9,FALSE)=0,"",VLOOKUP($A8,'Annex 2 Designated EHV charges'!$A:$P,9,FALSE)),"") -> 0.216 | F8: =IFERROR(IF(VLOOKUP($A8,'Annex 2 Designated EHV charges'!$A:$P,10,FALSE)=0,"",VLOOKUP($A8,'Annex 2 Designated EHV charges'!$A:$P,10,FALSE)),"") -> 11254.69 | G8: =IFERROR(IF(VLOOKUP($A8,'Annex 2 Designated EHV charges'!$A:$P,11,FALSE)=0,"",VLOOKUP($A8,'Annex 2 Designated EHV charges'!$A:$P,11,FALSE)),"") -> 2.59 | H8: =IFERROR(IF(VLOOKUP($A8,'Annex 2 Designated EHV charges'!$A:$P,12,FALSE)=0,"",VLOOKUP($A8,'Annex 2 Designated EHV charges'!$A:$P,12,FALSE)),"") -> 2.59
A9: {=IFERROR(INDEX('Annex 2 Designated EHV charges'!$A$11:$A$58, MATCH(0, IF(ISBLANK('Annex 2 Designated EHV charges'!$A$11:$A$58),1, COUNTIF(A$4:$A8, 'Annex 2 Designated EHV charges'!$A$11:$A$58)), 0)),"")} -> BLMBGS | B9: =IF($A9="","",VLOOKUP($A9,'Annex 2 Designated EHV charges'!$A:$O,2,0)) -> 821 | C9: =IF($A9="","",VLOOKUP($A9,'Annex 2 Designated EHV charges'!$A:$O,3,0)) -> 1200061385729;1200061385738 | D9: =IF($A9="","",VLOOKUP($A9,'Annex 2 Designated EHV charges'!$A:$O,7,0)) -> BLMBGS | E9: =IFERROR(IF(VLOOKUP($A9,'Annex 2 Designated EHV charges'!$A:$P,9,FALSE)=0,"",VLOOKUP($A9,'Annex 2 Designated EHV charges'!$A:$P,9,FALSE)),"") -> 0.215 | F9: =IFERROR(IF(VLOOKUP($A9,'Annex 2 Designated EHV charges'!$A:$P,10,FALSE)=0,"",VLOOKUP($A9,'Annex 2 Designated EHV charges'!$A:$P,10,FALSE)),"") -> 11254.69 | G9: =IFERROR(IF(VLOOKUP($A9,'Annex 2 Designated EHV charges'!$A:$P,11,FALSE)=0,"",VLOOKUP($A9,'Annex 2 Designated EHV charges'!$A:$P,11,FALSE)),"") -> 1.96 | H9: =IFERROR(IF(VLOOKUP($A9,'Annex 2 Designated EHV charges'!$A:$P,12,FALSE)=0,"",VLOOKUP($A9,'Annex 2 Designated EHV charges'!$A:$P,12,FALSE)),"") -> 1.96
A10: {=IFERROR(INDEX('Annex 2 Designated EHV charges'!$A$11:$A$58, MATCH(0, IF(ISBLANK('Annex 2 Designated EHV charges'!$A$11:$A$58),1, COUNTIF(A$4:$A9, 'Annex 2 Designated EHV charges'!$A$11:$A$58)), 0)),"")} -> BRDGTE | B10: =IF($A10="","",VLOOKUP($A10,'Annex 2 Designated EHV charges'!$A:$O,2,0)) -> 805 | C10: =IF($A10="","",VLOOKUP($A10,'Annex 2 Designated EHV charges'!$A:$O,3,0)) -> 1200061148014;1200061148023 | D10: =IF($A10="","",VLOOKUP($A10,'Annex 2 Designated EHV charges'!$A:$O,7,0)) -> BRDGTE | E10: =IFERROR(IF(VLOOKUP($A10,'Annex 2 Designated EHV charges'!$A:$P,9,FALSE)=0,"",VLOOKUP($A10,'Annex 2 Designated EHV charges'!$A:$P,9,FALSE)),"") -> 0.207 | F10: =IFERROR(IF(VLOOKUP($A10,'Annex 2 Designated EHV charges'!$A:$P,10,FALSE)=0,"",VLOOKUP($A10,'Annex 2 Designated EHV charges'!$A:$P,10,FALSE)),"") -> 11254.69 | G10: =IFERROR(IF(VLOOKUP($A10,'Annex 2 Designated EHV charges'!$A:$P,11,FALSE)=0,"",VLOOKUP($A10,'Annex 2 Designated EHV charges'!$A:$P,11,FALSE)),"") -> 3.34 | H10: =IFERROR(IF(VLOOKUP($A10,'Annex 2 Designated EHV charges'!$A:$P,12,FALSE)=0,"",VLOOKUP($A10,'Annex 2 Designated EHV charges'!$A:$P,12,FALSE)),"") -> 3.34
A11: {=IFERROR(INDEX('Annex 2 Designated EHV charges'!$A$11:$A$58, MATCH(0, IF(ISBLANK('Annex 2 Designated EHV charges'!$A$11:$A$58),1, COUNTIF(A$4:$A10, 'Annex 2 Designated EHV charges'!$A$11:$A$58)), 0)),"")} -> BRKFLD | B11: =IF($A11="","",VLOOKUP($A11,'Annex 2 Designated EHV charges'!$A:$O,2,0)) -> 829 | C11: =IF($A11="","",VLOOKUP($A11,'Annex 2 Designated EHV charges'!$A:$O,3,0)) -> 1200061148060;1200061148079 | D11: =IF($A11="","",VLOOKUP($A11,'Annex 2 Designated EHV charges'!$A:$O,7,0)) -> BRKFLD | E11: =IFERROR(IF(VLOOKUP($A11,'Annex 2 Designated EHV charges'!$A:$P,9,FALSE)=0,"",VLOOKUP($A11,'Annex 2 Designated EHV charges'!$A:$P,9,FALSE)),"") -> 0.22 | F11: =IFERROR(IF(VLOOKUP($A11,'Annex 2 Designated EHV charges'!$A:$P,10,FALSE)=0,"",VLOOKUP($A11,'Annex 2 Designated EHV charges'!$A:$P,10,FALSE)),"") -> 11254.69 | G11: =IFERROR(IF(VLOOKUP($A11,'Annex 2 Designated EHV charges'!$A:$P,11,FALSE)=0,"",VLOOKUP($A11,'Annex 2 Designated EHV charges'!$A:$P,11,FALSE)),"") -> 2.62 | H11: =IFERROR(IF(VLOOKUP($A11,'Annex 2 Designated EHV charges'!$A:$P,12,FALSE)=0,"",VLOOKUP($A11,'Annex 2 Designated EHV charges'!$A:$P,12,FALSE)),"") -> 2.62
A12: {=IFERROR(INDEX('Annex 2 Designated EHV charges'!$A$11:$A$58, MATCH(0, IF(ISBLANK('Annex 2 Designated EHV charges'!$A$11:$A$58),1, COUNTIF(A$4:$A11, 'Annex 2 Designated EHV charges'!$A$11:$A$58)), 0)),"")} -> BRMLEY | B12: =IF($A12="","",VLOOKUP($A12,'Annex 2 Designated EHV charges'!$A:$O,2,0)) -> 0 | C12: =IF($A12="","",VLOOKUP($A12,'Annex 2 Designated EHV charges'!$A:$O,3,0)) -> MSID: 1630 | D12: =IF($A12="","",VLOOKUP($A12,'Annex 2 Designated EHV charges'!$A:$O,7,0)) -> BRMLEY | E12: =IFERROR(IF(VLOOKUP($A12,'Annex 2 Designated EHV charges'!$A:$P,9,FALSE)=0,"",VLOOKUP($A12,'Annex 2 Designated EHV charges'!$A:$P,9,FALSE)),"") -> 0.212 | F12: =IFERROR(IF(VLOOKUP($A12,'Annex 2 Designated EHV charges'!$A:$P,10,FALSE)=0,"",VLOOKUP($A12,'Annex 2 Designated EHV charges'!$A:$P,10,FALSE)),"") -> 68626.32 | G12: =IFERROR(IF(VLOOKUP($A12,'Annex 2 Designated EHV charges'!$A:$P,11,FALSE)=0,"",VLOOKUP($A12,'Annex 2 Designated EHV charges'!$A:$P,11,FALSE)),"") -> 5.1 | H12: =IFERROR(IF(VLOOKUP($A12,'Annex 2 Designated EHV charges'!$A:$P,12,FALSE)=0,"",VLOOKUP($A12,'Annex 2 Designated EHV charges'!$A:$P,12,FALSE)),"") -> 5.1
A13: {=IFERROR(INDEX('Annex 2 Designated EHV charges'!$A$11:$A$58, MATCH(0, IF(ISBLANK('Annex 2 Designated EHV charges'!$A$11:$A$58),1, COUNTIF(A$4:$A12, 'Annex 2 Designated EHV charges'!$A$11:$A$58)), 0)),"")} -> CRLIMM | B13: =IF($A13="","",VLOOKUP($A13,'Annex 2 Designated EHV charges'!$A:$O,2,0)) -> 812 | C13: =IF($A13="","",VLOOKUP($A13,'Annex 2 Designated EHV charges'!$A:$O,3,0)) -> 1200062090483;1200062090492 | D13: =IF($A13="","",VLOOKUP($A13,'Annex 2 Designated EHV charges'!$A:$O,7,0)) -> CRLIMM | E13: =IFERROR(IF(VLOOKUP($A13,'Annex 2 Designated EHV charges'!$A:$P,9,FALSE)=0,"",VLOOKUP($A13,'Annex 2 Designated EHV charges'!$A:$P,9,FALSE)),"") -> 0.003 | F13: =IFERROR(IF(VLOOKUP($A13,'Annex 2 Designated EHV charges'!$A:$P,10,FALSE)=0,"",VLOOKUP($A13,'Annex 2 Designated EHV charges'!$A:$P,10,FALSE)),"") -> 82036.16 | G13: =IFERROR(IF(VLOOKUP($A13,'Annex 2 Designated EHV charges'!$A:$P,11,FALSE)=0,"",VLOOKUP($A13,'Annex 2 Designated EHV charges'!$A:$P,11,FALSE)),"") -> 1.5 | H13: =IFERROR(IF(VLOOKUP($A13,'Annex 2 Designated EHV charges'!$A:$P,12,FALSE)=0,"",VLOOKUP($A13,'Annex 2 Designated EHV charges'!$A:$P,12,FALSE)),"") -> 1.5
A14: {=IFERROR(INDEX('Annex 2 Designated EHV charges'!$A$11:$A$58, MATCH(0, IF(ISBLANK('Annex 2 Designated EHV charges'!$A$11:$A$58),1, COUNTIF(A$4:$A13, 'Annex 2 Designated EHV charges'!$A$11:$A$58)), 0)),"")} -> DART11 | B14: =IF($A14="","",VLOOKUP($A14,'Annex 2 Designated EHV charges'!$A:$O,2,0)) -> 0 | C14: =IF($A14="","",VLOOKUP($A14,'Annex 2 Designated EHV charges'!$A:$O,3,0)) -> MSID: 1032 | D14: =IF($A14="","",VLOOKUP($A14,'Annex 2 Designated EHV charges'!$A:$O,7,0)) -> DART11 | E14: =IFERROR(IF(VLOOKUP($A14,'Annex 2 Designated EHV charges'!$A:$P,9,FALSE)=0,"",VLOOKUP($A14,'Annex 2 Designated EHV charges'!$A:$P,9,FALSE)),"") -> 0.285 | F14: =IFERROR(IF(VLOOKUP($A14,'Annex 2 Designated EHV charges'!$A:$P,10,FALSE)=0,"",VLOOKUP($A14,'Annex 2 Designated EHV charges'!$A:$P,10,FALSE)),"") -> 10677.01 | G14: =IFERROR(IF(VLOOKUP($A14,'Annex 2 Designated EHV charges'!$A:$P,11,FALSE)=0,"",VLOOKUP($A14,'Annex 2 Designated EHV charges'!$A:$P,11,FALSE)),"") -> 6.51 | H14: =IFERROR(IF(VLOOKUP($A14,'Annex 2 Designated EHV charges'!$A:$P,12,FALSE)=0,"",VLOOKUP($A14,'Annex 2 Designated EHV charges'!$A:$P,12,FALSE)),"") -> 6.51
A15: {=IFERROR(INDEX('Annex 2 Designated EHV charges'!$A$11:$A$58, MATCH(0, IF(ISBLANK('Annex 2 Designated EHV charges'!$A$11:$A$58),1, COUNTIF(A$4:$A14, 'Annex 2 Designated EHV charges'!$A$11:$A$58)), 0)),"")} -> DART33 | B15: =IF($A15="","",VLOOKUP($A15,'Annex 2 Designated EHV charges'!$A:$O,2,0)) -> 0 | C15: =IF($A15="","",VLOOKUP($A15,'Annex 2 Designated EHV charges'!$A:$O,3,0)) -> MSID: 1032 | D15: =IF($A15="","",VLOOKUP($A15,'Annex 2 Designated EHV charges'!$A:$O,7,0)) -> DART33 | E15: =IFERROR(IF(VLOOKUP($A15,'Annex 2 Designated EHV charges'!$A:$P,9,FALSE)=0,"",VLOOKUP($A15,'Annex 2 Designated EHV charges'!$A:$P,9,FALSE)),"") -> 0.603 | F15: =IFERROR(IF(VLOOKUP($A15,'Annex 2 Designated EHV charges'!$A:$P,10,FALSE)=0,"",VLOOKUP($A15,'Annex 2 Designated EHV charges'!$A:$P,10,FALSE)),"") -> 28207.13 | G15: =IFERROR(IF(VLOOKUP($A15,'Annex 2 Designated EHV charges'!$A:$P,11,FALSE)=0,"",VLOOKUP($A15,'Annex 2 Designated EHV charges'!$A:$P,11,FALSE)),"") -> 7.02 | H15: =IFERROR(IF(VLOOKUP($A15,'Annex 2 Designated EHV charges'!$A:$P,12,FALSE)=0,"",VLOOKUP($A15,'Annex 2 Designated EHV charges'!$A:$P,12,FALSE)),"") -> 7.02
A16: {=IFERROR(INDEX('Annex 2 Designated EHV charges'!$A$11:$A$58, MATCH(0, IF(ISBLANK('Annex 2 Designated EHV charges'!$A$11:$A$58),1, COUNTIF(A$4:$A15, 'Annex 2 Designated EHV charges'!$A$11:$A$58)), 0)),"")} -> EPNLEI | B16: =IF($A16="","",VLOOKUP($A16,'Annex 2 Designated EHV charges'!$A:$O,2,0)) -> 0 | C16: =IF($A16="","",VLOOKUP($A16,'Annex 2 Designated EHV charges'!$A:$O,3,0)) -> MSID: 1628 | D16: =IF($A16="","",VLOOKUP($A16,'Annex 2 Designated EHV charges'!$A:$O,7,0)) -> EPNLEI | E16: =IFERROR(IF(VLOOKUP($A16,'Annex 2 Designated EHV charges'!$A:$P,9,FALSE)=0,"",VLOOKUP($A16,'Annex 2 Designated EHV charges'!$A:$P,9,FALSE)),"") -> 0.024 | F16: =IFERROR(IF(VLOOKUP($A16,'Annex 2 Designated EHV charges'!$A:$P,10,FALSE)=0,"",VLOOKUP($A16,'Annex 2 Designated EHV charges'!$A:$P,10,FALSE)),"") -> 68626.32 | G16: =IFERROR(IF(VLOOKUP($A16,'Annex 2 Designated EHV charges'!$A:$P,11,FALSE)=0,"",VLOOKUP($A16,'Annex 2 Designated EHV charges'!$A:$P,11,FALSE)),"") -> 5.2 | H16: =IFERROR(IF(VLOOKUP($A16,'Annex 2 Designated EHV charges'!$A:$P,12,FALSE)=0,"",VLOOKUP($A16,'Annex 2 Designated EHV charges'!$A:$P,12,FALSE)),"") -> 5.2
... A254: {=IFERROR(INDEX('Annex 2 Designated EHV charges'!$A$11:$A$58, MATCH(0, IF(ISBLANK('Annex 2 Designated EHV charges'!$A$11:$A$58),1, COUNTIF(A$4:$A253, 'Annex 2 Designated EHV charges'!$A$11:$A$58)), 0)),"")} | B254: =IF($A254="","",VLOOKUP($A254,'Annex 2 Designated EHV charges'!$A:$O,2,0)) | C254: =IF($A254="","",VLOOKUP($A254,'Annex 2 Designated EHV charges'!$A:$O,3,0)) | D254: =IF($A254="","",VLOOKUP($A254,'Annex 2 Designated EHV charges'!$A:$O,7,0)) | E254: =IFERROR(IF(VLOOKUP($A254,'Annex 2 Designated EHV charges'!$A:$P,9,FALSE)=0,"",VLOOKUP($A254,'Annex 2 Designated EHV charges'!$A:$P,9,FALSE)),"") | F254: =IFERROR(IF(VLOOKUP($A254,'Annex 2 Designated EHV charges'!$A:$P,10,FALSE)=0,"",VLOOKUP($A254,'Annex 2 Designated EHV charges'!$A:$P,10,FALSE)),"") | G254: =IFERROR(IF(VLOOKUP($A254,'Annex 2 Designated EHV charges'!$A:$P,11,FALSE)=0,"",VLOOKUP($A254,'Annex 2 Designated EHV charges'!$A:$P,11,FALSE)),"") | H254: =IFERROR(IF(VLOOKUP($A254,'Annex 2 Designated EHV charges'!$A:$P,12,FALSE)=0,"",VLOOKUP($A254,'Annex 2 Designated EHV charges'!$A:$P,12,FALSE)),"")

Sheet Annex 2b Export
A1: Note: The list of MPANs / MSIDs provided may be incomplete; the DNO reserves the right to apply the listed charges to any other MPANs / MSIDs associated with the site. Note: This table is automatically populated based on the content of the tab entitled 'Annex 2 Designated EHV charges'. The timebands are as shown in Annex 2.
A2: =Overview!B4& " - Effective from "&Overview!D4&" - "&Overview!E4&" Designated EHV export charges" -> London Power Networks - Effective from 1 April 2027 - Final Designated EHV export charges
A4: Export Unique Identifier | B4: LLFC/ DUoS Tariff ID | C4: Export MPANs/MSIDs | D4: Name | E4: ='Annex 2 Designated EHV charges'!M10 -> Export Super Red unit charge (p/kWh) | F4: ='Annex 2 Designated EHV charges'!N10 -> Export fixed charge (p/day) | G4: ='Annex 2 Designated EHV charges'!O10 -> Export capacity charge (p/kVA/day) | H4: ='Annex 2 Designated EHV charges'!P10 -> Export exceeded capacity charge (p/kVA/day)
A5: {=IFERROR(INDEX('Annex 2 Designated EHV charges'!$D$11:$D$58, MATCH(0, IF(ISBLANK('Annex 2 Designated EHV charges'!$D$11:$D$58),1, COUNTIF(A$4:$A4, 'Annex 2 Designated EHV charges'!$D$11:$D$58)), 0)),"")} -> NR_BOW | B5: =IF($A5="","",VLOOKUP($A5,'Annex 2 Designated EHV charges'!$D:$O,2,0)) -> 707 | C5: =IF($A5="","",VLOOKUP($A5,'Annex 2 Designated EHV charges'!$D:$O,3,0)) -> 1200060280430;1200060280459 | D5: =IF($A5="","",VLOOKUP($A5,'Annex 2 Designated EHV charges'!$D:$O,4,0)) -> NR_BOW | E5: =IFERROR(IF(VLOOKUP($A5,'Annex 2 Designated EHV charges'!$D:$P,10,FALSE)=0,"",VLOOKUP($A5,'Annex 2 Designated EHV charges'!$D:$P,10,FALSE)),"") | F5: =IFERROR(IF(VLOOKUP($A5,'Annex 2 Designated EHV charges'!$D:$P,11,FALSE)=0,"",VLOOKUP($A5,'Annex 2 Designated EHV charges'!$D:$P,11,FALSE)),"") | G5: =IFERROR(IF(VLOOKUP($A5,'Annex 2 Designated EHV charges'!$D:$P,12,FALSE)=0,"",VLOOKUP($A5,'Annex 2 Designated EHV charges'!$D:$P,12,FALSE)),"") | H5: =IFERROR(IF(VLOOKUP($A5,'Annex 2 Designated EHV charges'!$D:$P,13,FALSE)=0,"",VLOOKUP($A5,'Annex 2 Designated EHV charges'!$D:$P,13,FALSE)),"")
A6: {=IFERROR(INDEX('Annex 2 Designated EHV charges'!$D$11:$D$58, MATCH(0, IF(ISBLANK('Annex 2 Designated EHV charges'!$D$11:$D$58),1, COUNTIF(A$4:$A5, 'Annex 2 Designated EHV charges'!$D$11:$D$58)), 0)),"")} -> NR_W25 | B6: =IF($A6="","",VLOOKUP($A6,'Annex 2 Designated EHV charges'!$D:$O,2,0)) -> 703 | C6: =IF($A6="","",VLOOKUP($A6,'Annex 2 Designated EHV charges'!$D:$O,3,0)) -> 1200052486866 | D6: =IF($A6="","",VLOOKUP($A6,'Annex 2 Designated EHV charges'!$D:$O,4,0)) -> NR_W25 | E6: =IFERROR(IF(VLOOKUP($A6,'Annex 2 Designated EHV charges'!$D:$P,10,FALSE)=0,"",VLOOKUP($A6,'Annex 2 Designated EHV charges'!$D:$P,10,FALSE)),"") | F6: =IFERROR(IF(VLOOKUP($A6,'Annex 2 Designated EHV charges'!$D:$P,11,FALSE)=0,"",VLOOKUP($A6,'Annex 2 Designated EHV charges'!$D:$P,11,FALSE)),"") | G6: =IFERROR(IF(VLOOKUP($A6,'Annex 2 Designated EHV charges'!$D:$P,12,FALSE)=0,"",VLOOKUP($A6,'Annex 2 Designated EHV charges'!$D:$P,12,FALSE)),"") | H6: =IFERROR(IF(VLOOKUP($A6,'Annex 2 Designated EHV charges'!$D:$P,13,FALSE)=0,"",VLOOKUP($A6,'Annex 2 Designated EHV charges'!$D:$P,13,FALSE)),"")
A7: {=IFERROR(INDEX('Annex 2 Designated EHV charges'!$D$11:$D$58, MATCH(0, IF(ISBLANK('Annex 2 Designated EHV charges'!$D$11:$D$58),1, COUNTIF(A$4:$A6, 'Annex 2 Designated EHV charges'!$D$11:$D$58)), 0)),"")} -> NR_WES | B7: =IF($A7="","",VLOOKUP($A7,'Annex 2 Designated EHV charges'!$D:$O,2,0)) -> 716 | C7: =IF($A7="","",VLOOKUP($A7,'Annex 2 Designated EHV charges'!$D:$O,3,0)) -> 1200052486875 | D7: =IF($A7="","",VLOOKUP($A7,'Annex 2 Designated EHV charges'!$D:$O,4,0)) -> NR_WES | E7: =IFERROR(IF(VLOOKUP($A7,'Annex 2 Designated EHV charges'!$D:$P,10,FALSE)=0,"",VLOOKUP($A7,'Annex 2 Designated EHV charges'!$D:$P,10,FALSE)),"") | F7: =IFERROR(IF(VLOOKUP($A7,'Annex 2 Designated EHV charges'!$D:$P,11,FALSE)=0,"",VLOOKUP($A7,'Annex 2 Designated EHV charges'!$D:$P,11,FALSE)),"") -> 631.92 | G7: =IFERROR(IF(VLOOKUP($A7,'Annex 2 Designated EHV charges'!$D:$P,12,FALSE)=0,"",VLOOKUP($A7,'Annex 2 Designated EHV charges'!$D:$P,12,FALSE)),"") -> 0.05 | H7: =IFERROR(IF(VLOOKUP($A7,'Annex 2 Designated EHV charges'!$D:$P,13,FALSE)=0,"",VLOOKUP($A7,'Annex 2 Designated EHV charges'!$D:$P,13,FALSE)),"") -> 0.05
A8: {=IFERROR(INDEX('Annex 2 Designated EHV charges'!$D$11:$D$58, MATCH(0, IF(ISBLANK('Annex 2 Designated EHV charges'!$D$11:$D$58),1, COUNTIF(A$4:$A7, 'Annex 2 Designated EHV charges'!$D$11:$D$58)), 0)),"")} -> THAMEB | B8: =IF($A8="","",VLOOKUP($A8,'Annex 2 Designated EHV charges'!$D:$O,2,0)) -> 701 | C8: =IF($A8="","",VLOOKUP($A8,'Annex 2 Designated EHV charges'!$D:$O,3,0)) -> 1200050312030;1200050312040;1200061219394;1200050312059 | D8: =IF($A8="","",VLOOKUP($A8,'Annex 2 Designated EHV charges'!$D:$O,4,0)) -> THAMEB | E8: =IFERROR(IF(VLOOKUP($A8,'Annex 2 Designated EHV charges'!$D:$P,10,FALSE)=0,"",VLOOKUP($A8,'Annex 2 Designated EHV charges'!$D:$P,10,FALSE)),"") | F8: =IFERROR(IF(VLOOKUP($A8,'Annex 2 Designated EHV charges'!$D:$P,11,FALSE)=0,"",VLOOKUP($A8,'Annex 2 Designated EHV charges'!$D:$P,11,FALSE)),"") -> 1529.31 | G8: =IFERROR(IF(VLOOKUP($A8,'Annex 2 Designated EHV charges'!$D:$P,12,FALSE)=0,"",VLOOKUP($A8,'Annex 2 Designated EHV charges'!$D:$P,12,FALSE)),"") -> 0.05 | H8: =IFERROR(IF(VLOOKUP($A8,'Annex 2 Designated EHV charges'!$D:$P,13,FALSE)=0,"",VLOOKUP($A8,'Annex 2 Designated EHV charges'!$D:$P,13,FALSE)),"") -> 0.05
A9: {=IFERROR(INDEX('Annex 2 Designated EHV charges'!$D$11:$D$58, MATCH(0, IF(ISBLANK('Annex 2 Designated EHV charges'!$D$11:$D$58),1, COUNTIF(A$4:$A8, 'Annex 2 Designated EHV charges'!$D$11:$D$58)), 0)),"")} -> THAMEC | B9: =IF($A9="","",VLOOKUP($A9,'Annex 2 Designated EHV charges'!$D:$O,2,0)) -> 702 | C9: =IF($A9="","",VLOOKUP($A9,'Annex 2 Designated EHV charges'!$D:$O,3,0)) -> 1200061171342;1200061171351 | D9: =IF($A9="","",VLOOKUP($A9,'Annex 2 Designated EHV charges'!$D:$O,4,0)) -> THAMEC | E9: =IFERROR(IF(VLOOKUP($A9,'Annex 2 Designated EHV charges'!$D:$P,10,FALSE)=0,"",VLOOKUP($A9,'Annex 2 Designated EHV charges'!$D:$P,10,FALSE)),"") -> -0.002 | F9: =IFERROR(IF(VLOOKUP($A9,'Annex 2 Designated EHV charges'!$D:$P,11,FALSE)=0,"",VLOOKUP($A9,'Annex 2 Designated EHV charges'!$D:$P,11,FALSE)),"") -> 2358.99 | G9: =IFERROR(IF(VLOOKUP($A9,'Annex 2 Designated EHV charges'!$D:$P,12,FALSE)=0,"",VLOOKUP($A9,'Annex 2 Designated EHV charges'!$D:$P,12,FALSE)),"") -> 0.05 | H9: =IFERROR(IF(VLOOKUP($A9,'Annex 2 Designated EHV charges'!$D:$P,13,FALSE)=0,"",VLOOKUP($A9,'Annex 2 Designated EHV charges'!$D:$P,13,FALSE)),"") -> 0.05
A10: {=IFERROR(INDEX('Annex 2 Designated EHV charges'!$D$11:$D$58, MATCH(0, IF(ISBLANK('Annex 2 Designated EHV charges'!$D$11:$D$58),1, COUNTIF(A$4:$A9, 'Annex 2 Designated EHV charges'!$D$11:$D$58)), 0)),"")} -> BELVED | B10: =IF($A10="","",VLOOKUP($A10,'Annex 2 Designated EHV charges'!$D:$O,2,0)) -> 711 | C10: =IF($A10="","",VLOOKUP($A10,'Annex 2 Designated EHV charges'!$D:$O,3,0)) -> 1200060787118 | D10: =IF($A10="","",VLOOKUP($A10,'Annex 2 Designated EHV charges'!$D:$O,4,0)) -> BELVED | E10: =IFERROR(IF(VLOOKUP($A10,'Annex 2 Designated EHV charges'!$D:$P,10,FALSE)=0,"",VLOOKUP($A10,'Annex 2 Designated EHV charges'!$D:$P,10,FALSE)),"") | F10: =IFERROR(IF(VLOOKUP($A10,'Annex 2 Designated EHV charges'!$D:$P,11,FALSE)=0,"",VLOOKUP($A10,'Annex 2 Designated EHV charges'!$D:$P,11,FALSE)),"") -> 1033.4 | G10: =IFERROR(IF(VLOOKUP($A10,'Annex 2 Designated EHV charges'!$D:$P,12,FALSE)=0,"",VLOOKUP($A10,'Annex 2 Designated EHV charges'!$D:$P,12,FALSE)),"") -> 0.05 | H10: =IFERROR(IF(VLOOKUP($A10,'Annex 2 Designated EHV charges'!$D:$P,13,FALSE)=0,"",VLOOKUP($A10,'Annex 2 Designated EHV charges'!$D:$P,13,FALSE)),"") -> 0.05
A11: {=IFERROR(INDEX('Annex 2 Designated EHV charges'!$D$11:$D$58, MATCH(0, IF(ISBLANK('Annex 2 Designated EHV charges'!$D$11:$D$58),1, COUNTIF(A$4:$A10, 'Annex 2 Designated EHV charges'!$D$11:$D$58)), 0)),"")} -> SELCHP | B11: =IF($A11="","",VLOOKUP($A11,'Annex 2 Designated EHV charges'!$D:$O,2,0)) -> 730 | C11: =IF($A11="","",VLOOKUP($A11,'Annex 2 Designated EHV charges'!$D:$O,3,0)) -> 1200010258304 | D11: =IF($A11="","",VLOOKUP($A11,'Annex 2 Designated EHV charges'!$D:$O,4,0)) -> SELCHP | E11: =IFERROR(IF(VLOOKUP($A11,'Annex 2 Designated EHV charges'!$D:$P,10,FALSE)=0,"",VLOOKUP($A11,'Annex 2 Designated EHV charges'!$D:$P,10,FALSE)),"") -> -0.304 | F11: =IFERROR(IF(VLOOKUP($A11,'Annex 2 Designated EHV charges'!$D:$P,11,FALSE)=0,"",VLOOKUP($A11,'Annex 2 Designated EHV charges'!$D:$P,11,FALSE)),"") -> 5121.4 | G11: =IFERROR(IF(VLOOKUP($A11,'Annex 2 Designated EHV charges'!$D:$P,12,FALSE)=0,"",VLOOKUP($A11,'Annex 2 Designated EHV charges'!$D:$P,12,FALSE)),"") -> 0.05 | H11: =IFERROR(IF(VLOOKUP($A11,'Annex 2 Designated EHV charges'!$D:$P,13,FALSE)=0,"",VLOOKUP($A11,'Annex 2 Designated EHV charges'!$D:$P,13,FALSE)),"") -> 0.05
A12: {=IFERROR(INDEX('Annex 2 Designated EHV charges'!$D$11:$D$58, MATCH(0, IF(ISBLANK('Annex 2 Designated EHV charges'!$D$11:$D$58),1, COUNTIF(A$4:$A11, 'Annex 2 Designated EHV charges'!$D$11:$D$58)), 0)),"")} -> TLRSLN | B12: =IF($A12="","",VLOOKUP($A12,'Annex 2 Designated EHV charges'!$D:$O,2,0)) -> 0 | C12: =IF($A12="","",VLOOKUP($A12,'Annex 2 Designated EHV charges'!$D:$O,3,0)) -> MSID: 5538 | D12: =IF($A12="","",VLOOKUP($A12,'Annex 2 Designated EHV charges'!$D:$O,4,0)) -> TLRSLN | E12: =IFERROR(IF(VLOOKUP($A12,'Annex 2 Designated EHV charges'!$D:$P,10,FALSE)=0,"",VLOOKUP($A12,'Annex 2 Designated EHV charges'!$D:$P,10,FALSE)),"") -> -0.014 | F12: =IFERROR(IF(VLOOKUP($A12,'Annex 2 Designated EHV charges'!$D:$P,11,FALSE)=0,"",VLOOKUP($A12,'Annex 2 Designated EHV charges'!$D:$P,11,FALSE)),"") | G12: =IFERROR(IF(VLOOKUP($A12,'Annex 2 Designated EHV charges'!$D:$P,12,FALSE)=0,"",VLOOKUP($A12,'Annex 2 Designated EHV charges'!$D:$P,12,FALSE)),"") -> 0.05 | H12: =IFERROR(IF(VLOOKUP($A12,'Annex 2 Designated EHV charges'!$D:$P,13,FALSE)=0,"",VLOOKUP($A12,'Annex 2 Designated EHV charges'!$D:$P,13,FALSE)),"") -> 0.05
A13: {=IFERROR(INDEX('Annex 2 Designated EHV charges'!$D$11:$D$58, MATCH(0, IF(ISBLANK('Annex 2 Designated EHV charges'!$D$11:$D$58),1, COUNTIF(A$4:$A12, 'Annex 2 Designated EHV charges'!$D$11:$D$58)), 0)),"")} | B13: =IF($A13="","",VLOOKUP($A13,'Annex 2 Designated EHV charges'!$D:$O,2,0)) | C13: =IF($A13="","",VLOOKUP($A13,'Annex 2 Designated EHV charges'!$D:$O,3,0)) | D13: =IF($A13="","",VLOOKUP($A13,'Annex 2 Designated EHV charges'!$D:$O,4,0)) | E13: =IFERROR(IF(VLOOKUP($A13,'Annex 2 Designated EHV charges'!$D:$P,10,FALSE)=0,"",VLOOKUP($A13,'Annex 2 Designated EHV charges'!$D:$P,10,FALSE)),"") | F13: =IFERROR(IF(VLOOKUP($A13,'Annex 2 Designated EHV charges'!$D:$P,11,FALSE)=0,"",VLOOKUP($A13,'Annex 2 Designated EHV charges'!$D:$P,11,FALSE)),"") | G13: =IFERROR(IF(VLOOKUP($A13,'Annex 2 Designated EHV charges'!$D:$P,12,FALSE)=0,"",VLOOKUP($A13,'Annex 2 Designated EHV charges'!$D:$P,12,FALSE)),"") | H13: =IFERROR(IF(VLOOKUP($A13,'Annex 2 Designated EHV charges'!$D:$P,13,FALSE)=0,"",VLOOKUP($A13,'Annex 2 Designated EHV charges'!$D:$P,13,FALSE)),"")
A14: {=IFERROR(INDEX('Annex 2 Designated EHV charges'!$D$11:$D$58, MATCH(0, IF(ISBLANK('Annex 2 Designated EHV charges'!$D$11:$D$58),1, COUNTIF(A$4:$A13, 'Annex 2 Designated EHV charges'!$D$11:$D$58)), 0)),"")} | B14: =IF($A14="","",VLOOKUP($A14,'Annex 2 Designated EHV charges'!$D:$O,2,0)) | C14: =IF($A14="","",VLOOKUP($A14,'Annex 2 Designated EHV charges'!$D:$O,3,0)) | D14: =IF($A14="","",VLOOKUP($A14,'Annex 2 Designated EHV charges'!$D:$O,4,0)) | E14: =IFERROR(IF(VLOOKUP($A14,'Annex 2 Designated EHV charges'!$D:$P,10,FALSE)=0,"",VLOOKUP($A14,'Annex 2 Designated EHV charges'!$D:$P,10,FALSE)),"") | F14: =IFERROR(IF(VLOOKUP($A14,'Annex 2 Designated EHV charges'!$D:$P,11,FALSE)=0,"",VLOOKUP($A14,'Annex 2 Designated EHV charges'!$D:$P,11,FALSE)),"") | G14: =IFERROR(IF(VLOOKUP($A14,'Annex 2 Designated EHV charges'!$D:$P,12,FALSE)=0,"",VLOOKUP($A14,'Annex 2 Designated EHV charges'!$D:$P,12,FALSE)),"") | H14: =IFERROR(IF(VLOOKUP($A14,'Annex 2 Designated EHV charges'!$D:$P,13,FALSE)=0,"",VLOOKUP($A14,'Annex 2 Designated EHV charges'!$D:$P,13,FALSE)),"")
A15: {=IFERROR(INDEX('Annex 2 Designated EHV charges'!$D$11:$D$58, MATCH(0, IF(ISBLANK('Annex 2 Designated EHV charges'!$D$11:$D$58),1, COUNTIF(A$4:$A14, 'Annex 2 Designated EHV charges'!$D$11:$D$58)), 0)),"")} | B15: =IF($A15="","",VLOOKUP($A15,'Annex 2 Designated EHV charges'!$D:$O,2,0)) | C15: =IF($A15="","",VLOOKUP($A15,'Annex 2 Designated EHV charges'!$D:$O,3,0)) | D15: =IF($A15="","",VLOOKUP($A15,'Annex 2 Designated EHV charges'!$D:$O,4,0)) | E15: =IFERROR(IF(VLOOKUP($A15,'Annex 2 Designated EHV charges'!$D:$P,10,FALSE)=0,"",VLOOKUP($A15,'Annex 2 Designated EHV charges'!$D:$P,10,FALSE)),"") | F15: =IFERROR(IF(VLOOKUP($A15,'Annex 2 Designated EHV charges'!$D:$P,11,FALSE)=0,"",VLOOKUP($A15,'Annex 2 Designated EHV charges'!$D:$P,11,FALSE)),"") | G15: =IFERROR(IF(VLOOKUP($A15,'Annex 2 Designated EHV charges'!$D:$P,12,FALSE)=0,"",VLOOKUP($A15,'Annex 2 Designated EHV charges'!$D:$P,12,FALSE)),"") | H15: =IFERROR(IF(VLOOKUP($A15,'Annex 2 Designated EHV charges'!$D:$P,13,FALSE)=0,"",VLOOKUP($A15,'Annex 2 Designated EHV charges'!$D:$P,13,FALSE)),"")
A16: {=IFERROR(INDEX('Annex 2 Designated EHV charges'!$D$11:$D$58, MATCH(0, IF(ISBLANK('Annex 2 Designated EHV charges'!$D$11:$D$58),1, COUNTIF(A$4:$A15, 'Annex 2 Designated EHV charges'!$D$11:$D$58)), 0)),"")} | B16: =IF($A16="","",VLOOKUP($A16,'Annex 2 Designated EHV charges'!$D:$O,2,0)) | C16: =IF($A16="","",VLOOKUP($A16,'Annex 2 Designated EHV charges'!$D:$O,3,0)) | D16: =IF($A16="","",VLOOKUP($A16,'Annex 2 Designated EHV charges'!$D:$O,4,0)) | E16: =IFERROR(IF(VLOOKUP($A16,'Annex 2 Designated EHV charges'!$D:$P,10,FALSE)=0,"",VLOOKUP($A16,'Annex 2 Designated EHV charges'!$D:$P,10,FALSE)),"") | F16: =IFERROR(IF(VLOOKUP($A16,'Annex 2 Designated EHV charges'!$D:$P,11,FALSE)=0,"",VLOOKUP($A16,'Annex 2 Designated EHV charges'!$D:$P,11,FALSE)),"") | G16: =IFERROR(IF(VLOOKUP($A16,'Annex 2 Designated EHV charges'!$D:$P,12,FALSE)=0,"",VLOOKUP($A16,'Annex 2 Designated EHV charges'!$D:$P,12,FALSE)),"") | H16: =IFERROR(IF(VLOOKUP($A16,'Annex 2 Designated EHV charges'!$D:$P,13,FALSE)=0,"",VLOOKUP($A16,'Annex 2 Designated EHV charges'!$D:$P,13,FALSE)),"")
... A254: {=IFERROR(INDEX('Annex 2 Designated EHV charges'!$D$11:$D$58, MATCH(0, IF(ISBLANK('Annex 2 Designated EHV charges'!$D$11:$D$58),1, COUNTIF(A$4:$A253, 'Annex 2 Designated EHV charges'!$D$11:$D$58)), 0)),"")} | B254: =IF($A254="","",VLOOKUP($A254,'Annex 2 Designated EHV charges'!$D:$O,2,0)) | C254: =IF($A254="","",VLOOKUP($A254,'Annex 2 Designated EHV charges'!$D:$O,3,0)) | D254: =IF($A254="","",VLOOKUP($A254,'Annex 2 Designated EHV charges'!$D:$O,4,0)) | E254: =IFERROR(IF(VLOOKUP($A254,'Annex 2 Designated EHV charges'!$D:$P,10,FALSE)=0,"",VLOOKUP($A254,'Annex 2 Designated EHV charges'!$D:$P,10,FALSE)),"") | F254: =IFERROR(IF(VLOOKUP($A254,'Annex 2 Designated EHV charges'!$D:$P,11,FALSE)=0,"",VLOOKUP($A254,'Annex 2 Designated EHV charges'!$D:$P,11,FALSE)),"") | G254: =IFERROR(IF(VLOOKUP($A254,'Annex 2 Designated EHV charges'!$D:$P,12,FALSE)=0,"",VLOOKUP($A254,'Annex 2 Designated EHV charges'!$D:$P,12,FALSE)),"") | H254: =IFERROR(IF(VLOOKUP($A254,'Annex 2 Designated EHV charges'!$D:$P,13,FALSE)=0,"",VLOOKUP($A254,'Annex 2 Designated EHV charges'!$D:$P,13,FALSE)),"")

Sheet Annex 3 Preserved charges
A1: Back to Overview
A2: =Overview!B4& " - Effective from "&Overview!D4&" - "&Overview!E4&" LV and HV tariffs" -> London Power Networks - Effective from 1 April 2027 - Final LV and HV tariffs
A4: Supercustomer preserved charges/additional LLFCs/ DUoS Tariff IDs
B5: Closed LLFCs/ DUoS Tariff IDs | C5: PCs | D5: Red/black unit charge p/kWh | E5: Amber/yellow unit charge p/kWh | F5: Green unit charge p/kWh | G5: Fixed charge p/MPAN/day
A7: Notes: | B7: London Power Networks has no Preserved NHH Tariffs/Additional LLFCs/DUoS Tariff IDs
A12: Site Specific preserved charges/additional LLFCs/ DUoS Tariff IDs
B13: Closed LLFCs/ DUoS Tariff IDs | C13: PCs | D13: Red/black unit charge p/kWh | E13: Amber/yellow unit charge p/kWh | F13: Green unit charge p/kWh | G13: Fixed charge p/MPAN/day | H13: Capacity charge p/kVA/day | I13: Exceeded capacity charge p/kVA/day | J13: Reactive power charge p/kVArh
A15: Notes: | B15: London Power Networks has no Preserved HH Tariffs/Additional LLFCs/DUoS Tariff IDs

Sheet Annex 4 LDNO charges
A1: Back to Overview
A2: =Overview!B4& " - Effective from "&Overview!D4&" - "&Overview!E4&" LDNO tariffs" -> London Power Networks - Effective from 1 April 2027 - Final LDNO tariffs
A4: Time Bands for LV and HV Designated Properties | F4: Time Bands for Unmetered Properties
A5: Time periods | B5: Red Time Band | C5: Amber Time Band | D5: Green Time Band | H5: Black Time Band | I5: Yellow Time Band | J5: Green Time Band
A6: Monday to Friday (Including Bank Holidays) All Year | B6: 11:00 - 14:00 16:00 - 19:00 | C6: 07:00 - 11:00 14:00 - 16:00 19:00 - 23:00 | D6: 00:00 - 07:00 23:00 - 24:00 | F6: Monday to Friday (Including Bank Holidays) June to August Inclusive | H6: 11:00 - 14:00 | I6: 07:00 - 11:00 14:00 - 23:00 | J6: 00:00 - 07:00 23:00 - 24:00
A7: Saturday and Sunday All Year | D7: 00:00 - 24:00 | F7: Monday to Friday (Including Bank Holidays) November to February Inclusive | H7: 16:00 - 19:00 | I7: 07:00 - 16:00 19:00 - 23:00 | J7: 00:00 - 07:00 23:00 - 24:00
A8: Notes | B8: All the above times are in UK Clock time | F8: Monday to Friday (Including Bank Holidays) March, April, May and September, October | I8: 07:00 - 23:00 | J8: 00:00 - 07:00 23:00 - 24:00
F9: Saturday and Sunday All year | J9: 00:00 - 24:00
F10: Notes | H10: All the above times are in UK Clock time
A13: Tariff name | B13: Unique billing identifier | C13: PCs | D13: Red/black unit charge p/kWh | E13: Amber/yellow unit charge p/kWh | F13: Green unit charge p/kWh | G13: Fixed charge p/MPAN/day | H13: Capacity charge p/kVA/day | I13: Exceeded capacity charge p/kVA/day | J13: Reactive power charge p/kVArh
A14: LDNO LV: Domestic Aggregated or CT with Residual | B14: A00 | C14: 0, 1, 2 | D14: 8.454 | E14: 0.861 | F14: 0 | G14: 0
A15: LDNO LV: Domestic Aggregated (Related MPAN) | B15: B00 | C15: 2 | D15: 8.604 | E15: 1.012 | F15: 0.075
A16: LDNO LV: Non-Domestic Aggregated or CT No Residual | B16: C00 | C16: 0, 3, 4, 5-8 | D16: 6.661 | E16: 0.784 | F16: 0.058 | G16: 4.1
A17: LDNO LV: Non-Domestic Aggregated or CT Band 1 | B17: C01 | C17: 0, 3, 4, 5-8 | D17: 6.578 | E17: 0.7 | F17: 0 | G17: 0
A18: LDNO LV: Non-Domestic Aggregated or CT Band 2 | B18: C02 | C18: 0, 3, 4, 5-8 | D18: 5.991 | E18: 0.114 | F18: 0 | G18: 0
A19: LDNO LV: Non-Domestic Aggregated or CT Band 3 | B19: C03 | C19: 0, 3, 4, 5-8 | D19: 5.776 | E19: 0 | F19: 0 | G19: 0
A20: LDNO LV: Non-Domestic Aggregated or CT Band 4 | B20: C04 | C20: 0, 3, 4, 5-8 | D20: 5.498 | E20: 0 | F20: 0 | G20: 0
A21: LDNO LV: Non-Domestic Aggregated (Related MPAN) | B21: D00 | C21: 4 | D21: 6.661 | E21: 0.784 | F21: 0.058
A22: LDNO LV: LV Site Specific No Residual | B22: E00 | C22: 0 | D22: 5.295 | E22: 0.639 | F22: 0.043 | G22: 10.05 | H22: 5.73 | I22: 5.73 | J22: 0.407
A23: LDNO LV: LV Site Specific Band 1 | B23: E01 | C23: 0 | D23: 3.387 | E23: 0.223 | F23: 0.021 | G23: 1.59 | H23: 5.73 | I23: 5.73 | J23: 0.407
A24: LDNO LV: LV Site Specific Band 2 | B24: E02 | C24: 0 | D24: 3.342 | E24: 0.223 | F24: 0.021 | G24: 1.59 | H24: 5.73 | I24: 5.73 | J24: 0.407
A25: LDNO LV: LV Site Specific Band 3 | B25: E03 | C25: 0 | D25: 3.301 | E25: 0.223 | F25: 0.021 | G25: 1.59 | H25: 5.73 | I25: 5.73 | J25: 0.407
A26: LDNO LV: LV Site Specific Band 4 | B26: E04 | C26: 0 | D26: 3.252 | E26: 0.223 | F26: 0.021 | G26: 1.59 | H26: 5.73 | I26: 5.73 | J26: 0.407
A27: LDNO LV: Unmetered Supplies | B27: U00 | C27: 0, 1 or 8 | D27: 28.398 | E27: 2.319 | F27: 0.326
A28: LDNO LV: LV Generation Aggregated | B28: F00 | C28: 0, 8 | D28: -7.828 | E28: -0.921 | F28: -0.068 | G28: 0
A29: LDNO LV: LV Generation Site Specific | B29: G00 | C29: 0 | D29: -7.828 | E29: -0.921 | F29: -0.068 | G29: 0 | J29: 0.55
A30: LDNO HV: Domestic Aggregated or CT with Residual | B30: A10 | C30: 0, 1, 2 | D30: 6.533 | E30: 0.666 | F30: 0 | G30: 0
A31: LDNO HV: Domestic Aggregated (Related MPAN) | B31: B10 | C31: 2 | D31: 6.65 | E31: 0.782 | F31: 0.058
A32: LDNO HV: Non-Domestic Aggregated or CT No Residual | B32: C10 | C32: 0, 3, 4, 5-8 | D32: 5.148 | E32: 0.606 | F32: 0.045 | G32: 3.17
A33: LDNO HV: Non-Domestic Aggregated or CT Band 1 | B33: C11 | C33: 0, 3, 4, 5-8 | D33: 5.084 | E33: 0.541 | F33: 0 | G33: 0
A34: LDNO HV: Non-Domestic Aggregated or CT Band 2 | B34: C12 | C34: 0, 3, 4, 5-8 | D34: 4.63 | E34: 0.088 | F34: 0 | G34: 0
A35: LDNO HV: Non-Domestic Aggregated or CT Band 3 | B35: C13 | C35: 0, 3, 4, 5-8 | D35: 4.464 | E35: 0 | F35: 0 | G35: 0
A36: LDNO HV: Non-Domestic Aggregated or CT Band 4 | B36: C14 | C36: 0, 3, 4, 5-8 | D36: 4.249 | E36: 0 | F36: 0 | G36: 0
A37: LDNO HV: Non-Domestic Aggregated (Related MPAN) | B37: D10 | C37: 4 | D37: 5.148 | E37: 0.606 | F37: 0.045
A38: LDNO HV: LV Site Specific No Residual | B38: E10 | C38: 0 | D38: 4.092 | E38: 0.494 | F38: 0.033 | G38: 7.77 | H38: 4.43 | I38: 4.43 | J38: 0.315
A39: LDNO HV: LV Site Specific Band 1 | B39: E11 | C39: 0 | D39: 2.617 | E39: 0.173 | F39: 0.016 | G39: 1.23 | H39: 4.43 | I39: 4.43 | J39: 0.315
A40: LDNO HV: LV Site Specific Band 2 | B40: E12 | C40: 0 | D40: 2.583 | E40: 0.173 | F40: 0.016 | G40: 1.23 | H40: 4.43 | I40: 4.43 | J40: 0.315
A41: LDNO HV: LV Site Specific Band 3 | B41: E13 | C41: 0 | D41: 2.551 | E41: 0.173 | F41: 0.016 | G41: 1.23 | H41: 4.43 | I41: 4.43 | J41: 0.315
A42: LDNO HV: LV Site Specific Band 4 | B42: E14 | C42: 0 | D42: 2.513 | E42: 0.173 | F42: 0.016 | G42: 1.23 | H42: 4.43 | I42: 4.43 | J42: 0.315
A43: LDNO HV: LV Sub Site Specific No Residual | B43: J10 | C43: 0 | D43: 3.668 | E43: 0.469 | F43: 0.025 | G43: 9.55 | H43: 8.12 | I43: 8.12 | J43: 0.272
...

Sheet Annex 5 LLFs
A1: Back to Overview
A2: This table has intentionally been left blank. The line loss factors that are approved by the BSC Panel for the applicable year and consequently published on the Elexon website will take precedence and be used in Settlement. This annex will be re-published once these values are available.
A3: =Overview!B4& " - Illustrative LLFs for year beginning "&Overview!D4 -> London Power Networks - Illustrative LLFs for year beginning 1 April 2027
A5: Time periods | C5: Period 1 | D5: Period 2 | E5: Period 3 | F5: Period 4 | G5: Period 5
C6: Winter Peak | D6: Summer Peak | E6: Winter Shoulder | F6: Night | G6: Other
A7: Monday to Friday November to February | C7: 16:00 - 20:00 | E7: 07:00 - 16:00
A8: Monday to Friday June to August | D8: 07:00 - 20:00
A9: Monday to Friday March | E9: 07:00 - 20:00
A10: All Year | F10: 00:00 - 07:00 | G10: All Other Times
A11: Notes | C11: All the above times are in UK Clock time
A13: Generic demand and generation LLFs
A14: Metered voltage, respective periods and associated LLFCs/DUoS Tariff IDs
A15: Metered voltage | B15: Period 1 | C15: Period 2 | D15: Period 3 | E15: Period 4 | F15: Period 5 | G15: Associated LLFC/DUoS Tariff ID
A16: Low-voltage network
A17: Low-voltage substation
A18: High-voltage network
A19: High-voltage substation
A20: 33kV generic
A21: 132kV generic
A23: EHV site specific LLFs
A24: Demand
A25: Site | B25: Period 1 | C25: Period 2 | D25: Period 3 | E25: Period 4 | F25: Period 5 | G25: Associated LLFC/DUoS Tariff ID
A26: Site 1
A27: Site 2
A28: Site 3
A29: Site 4
A30: Site 5
A32: EHV site specific LLFs
A33: Generation
A34: Site | B34: Period 1 | C34: Period 2 | D34: Period 3 | E34: Period 4 | F34: Period 5 | G34: Associated LLFC/DUoS Tariff ID
A35: Site 1
A36: Site 2
A37: Site 3
A38: Site 4
A39: Site 5
A41: CVA site specific LLFs
A42: Site | B42: Period 1 | C42: Period 2 | D42: Period 3 | E42: Period 4 | F42: Period 5 | G42: MSID
A43: Site 1
A44: Site 2
A45: Site 3
...

Sheet Annex 6 New or Amended EHV
A1: Back to Overview | D1: Note: The DNO reserves the right to apply the listed charges to any other MPANs/MSIDs associated with the site. This includes reallocating charges to a traded MPAN at the same site where another MPAN has been disconnected or de-energised. If sites appear in both Annex 2 and Annex 6, the charges in Annex 6 take precedence. Where an existing Designated EHV Property is modified and energised in the charging year, we may revise the EDCM charges for the modified Designated EHV Property.
A2: Annex 6 - Charges for New or Amended Designated EHV Properties
A4: =Overview!B4& " - Effective from "&Overview!D4&" - "&Overview!E4&" new designated EHV charges" -> London Power Networks - Effective from 1 April 2027 - Final new designated EHV charges
A5: Effective from date | B5: Import Unique Identifier | C5: LLFC/ DUoS Tariff ID | D5: Import MPANs/MSIDs | E5: Export Unique Identifier | F5: LLFC/ DUoS Tariff ID | G5: Export MPANs/MSIDs | H5: Name | I5: Residual Charging Band | J5: ='Annex 2 Designated EHV charges'!I10 -> Import Super Red unit charge (p/kWh) | K5: ='Annex 2 Designated EHV charges'!J10 -> Import fixed charge (p/day) | L5: ='Annex 2 Designated EHV charges'!K10 -> Import capacity charge (p/kVA/day) | M5: ='Annex 2 Designated EHV charges'!L10 -> Import exceeded capacity charge (p/kVA/day) | N5: ='Annex 2 Designated EHV charges'!M10 -> Export Super Red unit charge (p/kWh) | O5: ='Annex 2 Designated EHV charges'!N10 -> Export fixed charge (p/day) | P5: ='Annex 2 Designated EHV charges'!O10 -> Export capacity charge (p/kVA/day) | Q5: ='Annex 2 Designated EHV charges'!P10 -> Export exceeded capacity charge (p/kVA/day)
A6: 01/04/2027 | B6: THAMEC | C6: 802 | D6: 1200061171324;1200061171333 | E6: THAMEC | F6: 702 | G6: 1200061171342;1200061171351 | H6: THAMEC | I6: 4 | J6: 0 | K6: 73260.99 | L6: 1.9 | M6: 1.9 | N6: -0.002 | O6: 1084.47 | P6: 0.05 | Q6: 0.05
A17: =Overview!B4& " - Effective from "&Overview!D4&" - "&Overview!E4&" new designated EHV line loss factors" -> London Power Networks - Effective from 1 April 2027 - Final new designated EHV line loss factors
A18: Effective from date | B18: Import Unique Identifier | C18: LLFC/ DUoS Tariff ID | D18: Import MPANs/MSIDs | E18: Export Unique Identifier | F18: LLFC/ DUoS Tariff ID | G18: Export MPANs/MSIDs | H18: Name | I18: Residual Charging Band | J18: Import LLF period 1 | K18: Import LLF period 2 | L18: Import LLF period 3 | M18: Import LLF period 4 | N18: Import LLF period 5 | O18: Export LLF period 1 | P18: Export LLF period 2 | Q18: Export LLF period 3 | R18: Export LLF period 4 | S18: Export LLF period 5

Sheet Annex 7 Pass-Through Costs
A1: Back to Overview
A2: =""&Overview!B4& " - Effective from "&Overview!D4&" - "&Overview!E4&" Supplier of Last Resort and Eligible Bad Debt Pass-Through Costs" -> London Power Networks - Effective from 1 April 2027 - Final Supplier of Last Resort and Eligible Bad Debt Pass-Through Costs
A4: Tariff name | B4: Open LLFCs/ DUoS Tariff IDs / LDNO unique billing identifier | C4: PCs | D4: Supplier of Last Resort Fixed charge adder* p/MPAN/day | E4: Eligible Bad Debt Fixed charge adder** p/MPAN/day
A5: Domestic Aggregated or CT with Residual | B5: =IFERROR(INDEX('Annex 1 LV, HV and UMS charges'!$B$13:$B$44,MATCH($A5,'Annex 1 LV, HV and UMS charges'!$A$13:$A$44,0)),IF(INDEX('Annex 4 LDNO charges'!$B$12:$B$202,MATCH($A5,'Annex 4 LDNO charges'!$A$12:$A$202,0))=0,"",INDEX('Annex 4 LDNO charges'!$B$12:$B$202,MATCH($A5,'Annex 4 LDNO charges'!$A$12:$A$202,0)))) -> 1 | C5: =IFERROR(INDEX('Annex 1 LV, HV and UMS charges'!$C$13:$C$44,MATCH($A5,'Annex 1 LV, HV and UMS charges'!$A$13:$A$44,0)),INDEX('Annex 4 LDNO charges'!$C$12:$C$202,MATCH($A5,'Annex 4 LDNO charges'!$A$12:$A$202,0))) -> 0, 1, 2 | D5: 0 | E5: 0
A6: Non-Domestic Aggregated or CT No Residual | B6: =IFERROR(INDEX('Annex 1 LV, HV and UMS charges'!$B$13:$B$44,MATCH($A6,'Annex 1 LV, HV and UMS charges'!$A$13:$A$44,0)),IF(INDEX('Annex 4 LDNO charges'!$B$12:$B$202,MATCH($A6,'Annex 4 LDNO charges'!$A$12:$A$202,0))=0,"",INDEX('Annex 4 LDNO charges'!$B$12:$B$202,MATCH($A6,'Annex 4 LDNO charges'!$A$12:$A$202,0)))) -> 199 | C6: =IFERROR(INDEX('Annex 1 LV, HV and UMS charges'!$C$13:$C$44,MATCH($A6,'Annex 1 LV, HV and UMS charges'!$A$13:$A$44,0)),INDEX('Annex 4 LDNO charges'!$C$12:$C$202,MATCH($A6,'Annex 4 LDNO charges'!$A$12:$A$202,0))) -> 0, 3, 4, 5-8 | E6: 0
